<?xml version="1.0"?>
<robot name="gimbal">

  <!-- 底座（固定在地面） -->
  <link name="base">
    <visual>
      <geometry><box size="0.2 0.2 0.05"/></geometry>
    </visual>
    <collision>
      <geometry><box size="0.2 0.2 0.05"/></geometry>
    </collision>
    <inertial>
      <mass value="1.0"/>
      <inertia ixx="0.01" iyy="0.01" izz="0.01" ixy="0" ixz="0" iyz="0"/>
    </inertial>
  </link>

  <!-- Yaw 轴连杆 -->
  <link name="yaw_link">
    <visual>
      <geometry><cylinder radius="0.05" length="0.1"/></geometry>
    </visual>
    <collision>
      <geometry><cylinder radius="0.05" length="0.1"/></geometry>
    </collision>
    <inertial>
      <mass value="0.5"/>
      <inertia ixx="0.005" iyy="0.005" izz="0.005" ixy="0" ixz="0" iyz="0"/>
    </inertial>
  </link>

  <!-- Yaw 关节：绕 Z 轴旋转，±180° -->
  <joint name="yaw_joint" type="revolute">
    <parent link="base"/>
    <child link="yaw_link"/>
    <origin xyz="0 0 0.075" rpy="0 0 0"/>
    <axis xyz="0 0 1"/>
    <limit lower="-3.14159" upper="3.14159" effort="10.0" velocity="3.14"/>
  </joint>

  <!-- Pitch 轴连杆（挂载相机） -->
  <link name="pitch_link">
    <visual>
      <geometry><box size="0.08 0.08 0.05"/></geometry>
    </visual>
    <collision>
      <geometry><box size="0.08 0.08 0.05"/></geometry>
    </collision>
    <inertial>
      <mass value="0.3"/>
      <inertia ixx="0.002" iyy="0.002" izz="0.002" ixy="0" ixz="0" iyz="0"/>
    </inertial>
  </link>

  <!-- Pitch 关节：绕 Y 轴旋转，-90° ~ +90° -->
  <joint name="pitch_joint" type="revolute">
    <parent link="yaw_link"/>
    <child link="pitch_link"/>
    <origin xyz="0 0 0.1" rpy="0 0 0"/>
    <axis xyz="0 1 0"/>
    <limit lower="-1.5708" upper="1.5708" effort="10.0" velocity="3.14"/>
  </joint>
  <link name="camera_link">
    <inertial>
      <mass value="0.001"/>
      <inertia ixx="0.000001" iyy="0.000001" izz="0.000001"
               ixy="0" ixz="0" iyz="0"/>
    </inertial>
  </link>

  <joint name="camera_joint" type="fixed">
    <parent link="pitch_link"/>
    <child link="camera_link"/>
    <origin xyz="0.05 0.0 0.0" rpy="0 0 0"/>
  </joint>

</robot>